[2022-10-13 09:34:07,386] {taskinstance.py:1159} INFO - Dependencies all met for <TaskInstance: dbt_snow_dag_test.dbt_pre_stage_run manual__2022-10-13T09:34:06.290587+00:00 [queued]>
[2022-10-13 09:34:07,394] {taskinstance.py:1159} INFO - Dependencies all met for <TaskInstance: dbt_snow_dag_test.dbt_pre_stage_run manual__2022-10-13T09:34:06.290587+00:00 [queued]>
[2022-10-13 09:34:07,395] {taskinstance.py:1356} INFO - 
--------------------------------------------------------------------------------
[2022-10-13 09:34:07,395] {taskinstance.py:1357} INFO - Starting attempt 1 of 2
[2022-10-13 09:34:07,395] {taskinstance.py:1358} INFO - 
--------------------------------------------------------------------------------
[2022-10-13 09:34:07,410] {taskinstance.py:1377} INFO - Executing <Task(BashOperator): dbt_pre_stage_run> on 2022-10-13 09:34:06.290587+00:00
[2022-10-13 09:34:07,413] {standard_task_runner.py:52} INFO - Started process 88 to run task
[2022-10-13 09:34:07,415] {standard_task_runner.py:79} INFO - Running: ['***', 'tasks', 'run', 'dbt_snow_dag_test', 'dbt_pre_stage_run', 'manual__2022-10-13T09:34:06.290587+00:00', '--job-id', '3', '--raw', '--subdir', 'DAGS_FOLDER/dbt_snow.py', '--cfg-path', '/tmp/tmp6mncrp_y', '--error-file', '/tmp/tmp01j0fv7n']
[2022-10-13 09:34:07,416] {standard_task_runner.py:80} INFO - Job 3: Subtask dbt_pre_stage_run
[2022-10-13 09:34:07,466] {task_command.py:369} INFO - Running <TaskInstance: dbt_snow_dag_test.dbt_pre_stage_run manual__2022-10-13T09:34:06.290587+00:00 [running]> on host 7a2aacc6344e
[2022-10-13 09:34:07,511] {taskinstance.py:1889} ERROR - Task failed with exception
Traceback (most recent call last):
  File "/home/airflow/.local/lib/python3.7/site-packages/airflow/models/taskinstance.py", line 1451, in _run_raw_task
    self._execute_task_with_callbacks(context, test_mode)
  File "/home/airflow/.local/lib/python3.7/site-packages/airflow/models/taskinstance.py", line 1555, in _execute_task_with_callbacks
    task_orig = self.render_templates(context=context)
  File "/home/airflow/.local/lib/python3.7/site-packages/airflow/models/taskinstance.py", line 2202, in render_templates
    rendered_task = self.task.render_template_fields(context)
  File "/home/airflow/.local/lib/python3.7/site-packages/airflow/models/baseoperator.py", line 1179, in render_template_fields
    self._do_render_template_fields(self, self.template_fields, context, jinja_env, set())
  File "/home/airflow/.local/lib/python3.7/site-packages/airflow/utils/session.py", line 71, in wrapper
    return func(*args, session=session, **kwargs)
  File "/home/airflow/.local/lib/python3.7/site-packages/airflow/models/abstractoperator.py", line 348, in _do_render_template_fields
    seen_oids,
  File "/home/airflow/.local/lib/python3.7/site-packages/airflow/models/abstractoperator.py", line 404, in render_template
    return {key: self.render_template(value, context, jinja_env) for key, value in value.items()}
  File "/home/airflow/.local/lib/python3.7/site-packages/airflow/models/abstractoperator.py", line 404, in <dictcomp>
    return {key: self.render_template(value, context, jinja_env) for key, value in value.items()}
  File "/home/airflow/.local/lib/python3.7/site-packages/airflow/models/abstractoperator.py", line 391, in render_template
    return render_template_to_string(template, context)
  File "/home/airflow/.local/lib/python3.7/site-packages/airflow/utils/helpers.py", line 296, in render_template_to_string
    return render_template(template, context, native=False)
  File "/home/airflow/.local/lib/python3.7/site-packages/airflow/utils/helpers.py", line 291, in render_template
    return "".join(nodes)
  File "<template>", line 12, in root
  File "/home/airflow/.local/lib/python3.7/site-packages/jinja2/sandbox.py", line 326, in getattr
    value = getattr(obj, attribute)
  File "/home/airflow/.local/lib/python3.7/site-packages/airflow/utils/context.py", line 100, in __getattr__
    self.var = Variable.get(key, deserialize_json=self._deserialize_json)
  File "/home/airflow/.local/lib/python3.7/site-packages/airflow/models/variable.py", line 138, in get
    raise KeyError(f'Variable {key} does not exist')
KeyError: 'Variable dbt_user does not exist'
[2022-10-13 09:34:07,521] {taskinstance.py:1400} INFO - Marking task as UP_FOR_RETRY. dag_id=dbt_snow_dag_test, task_id=dbt_pre_stage_run, execution_date=20221013T093406, start_date=20221013T093407, end_date=20221013T093407
[2022-10-13 09:34:07,533] {standard_task_runner.py:97} ERROR - Failed to execute job 3 for task dbt_pre_stage_run ('Variable dbt_user does not exist'; 88)
[2022-10-13 09:34:07,547] {local_task_job.py:156} INFO - Task exited with return code 1
[2022-10-13 09:34:07,609] {local_task_job.py:273} INFO - 0 downstream tasks scheduled from follow-on schedule check
